Workbook

Sheet Instructions
A1: SESSION 21 – Case Study Integration + Mini Dashboard
A2: Task | B2: How to practice
A3: 1 | B3: Use Raw_Orders as the sample food-delivery dataset. Remove the duplicate row, standardize dates, and replace blank Delivery Partner values with Unassigned. Cleaned_Orders contains the expected cleaned structure.
A4: 2 | B4: Use XLOOKUP or VLOOKUP in Cleaned_Orders to fetch Restaurant Name from Restaurant_Details using Restaurant ID.
A5: 3 | B5: Add Day of Week using =TEXT([@[Delivery Date]],"dddd") or =TEXT(F2,"dddd").
A6: 4 | B6: Use the City_Summary sheet as the expected city-level summary. Create the same summary with a PivotTable in desktop Excel and insert a column/bar PivotChart.
A7: 5 | B7: Use Mini Dashboard as the finished practice dashboard. Native Excel slicers require creating a PivotTable/PivotChart in desktop Excel; the City_Filter sheet provides the city filter list for practice.
A8: Note | B8: The workbook includes sample data so no external download is required. It is intentionally Swiggy/Zomato-style sample data, not proprietary company data.

Sheet Mini Dashboard
B2: FOOD DELIVERY MINI DASHBOARD
B4: Case Study Integration | Orders • Delivery Time • Restaurants • City Analysis
B6: TOTAL ORDERS | E6: AVG DELIVERY TIME | H6: TOP RESTAURANT | K6: CITIES
B8: =COUNTA(Cleaned_Orders!$A$2:$A$41) -> 40 | E8: =ROUND(AVERAGE(Cleaned_Orders!$G$2:$G$41),1)&" min" -> 46.5 min | H8: =INDEX(Top_Restaurants!$A$2:$A$9,MATCH(MAX(Top_Restaurants!$B$2:$B$9),Top_Restaurants!$B$2:$B$9,0)) -> Dosa Junction | K8: =SUMPRODUCT(1/COUNTIF(Cleaned_Orders!$C$2:$C$41,Cleaned_Orders!$C$2:$C$41)) -> 4
B11: TOP 3 RESTAURANTS BY ORDERS | H11: CITY FILTER / SLICER PRACTICE
B12: =Top_Restaurants!A2 -> Dosa Junction | E12: =Top_Restaurants!B2 -> 8 | H12: City
B13: =Top_Restaurants!A3 -> Pasta Street | E13: =Top_Restaurants!B3 -> 6 | H13: All Cities
B14: =Top_Restaurants!A4 -> Pizza Corner | E14: =Top_Restaurants!B4 -> 6 | H14: Rajkot
H15: Ahmedabad
H16: Surat
H17: Vadodara
H19: Native Excel slicer note: Create a PivotTable from Cleaned_Orders, insert a PivotChart, then Insert → Slicer → City.

Sheet Raw_Orders
A1: Order ID | B1: Restaurant ID | C1: City | D1: Order Amount | E1: Delivery Charge | F1: Delivery Date | G1: Delivery Time (min) | H1: Delivery Partner
A2: O001 | B2: R003 | C2: Surat | D2: 1036 | E2: 70 | F2: 46224 | G2: 48 | H2: Neha
A3: O002 | B3: R008 | C3: Vadodara | D3: 622 | E3: 50 | F3: 46209 | G3: 54 | H3: Karan
A4: O003 | B4: R004 | C4: Vadodara | D4: 186 | E4: 20 | F4: 46233 | G4: 45 | H4: Karan
A5: O004 | B5: R007 | C5: Surat | D5: 321 | E5: 30 | F5: 46233 | G5: 36 | H5: Amit
A6: O005 | B6: R001 | C6: Rajkot | D6: 1074 | E6: 70 | F6: 46223 | G6: 48 | H6: Priya
A7: O006 | B7: R001 | C7: Rajkot | D7: 853 | E7: 60 | F7: 46226 | G7: 53 | H7: Rahul
A8: O007 | B8: R006 | C8: Ahmedabad | D8: 227 | E8: 30 | F8: 46207 | G8: 27 | H8: Rahul
A9: O008 | B9: R008 | C9: Vadodara | D9: 509 | E9: 60 | F9: 46214 | G9: 68 | H9: Priya
A10: O009 | B10: R008 | C10: Vadodara | D10: 489 | E10: 30 | F10: 02/07/2026 | G10: 64 | H10: Priya
A11: O010 | B11: R004 | C11: Vadodara | D11: 332 | E11: 30 | F11: 46225 | G11: 35
A12: O011 | B12: R002 | C12: Ahmedabad | D12: 430 | E12: 60 | F12: 46221 | G12: 52 | H12: Priya
A13: O012 | B13: R004 | C13: Vadodara | D13: 878 | E13: 30 | F13: 46217 | G13: 56 | H13: Neha
A14: O013 | B14: R006 | C14: Ahmedabad | D14: 1104 | E14: 60 | F14: 46214 | G14: 46 | H14: Priya
A15: O014 | B15: R007 | C15: Surat | D15: 724 | E15: 20 | F15: 46209 | G15: 27
A16: O015 | B16: R008 | C16: Vadodara | D16: 185 | E16: 50 | F16: 07-18-2026 | G16: 26 | H16: Karan
A17: O016 | B17: R004 | C17: Vadodara | D17: 832 | E17: 60 | F17: 46207 | G17: 61 | H17: Amit
A18: O017 | B18: R003 | C18: Surat | D18: 893 | E18: 40 | F18: 46228 | G18: 44 | H18: Karan
A19: O018 | B19: R005 | C19: Rajkot | D19: 683 | E19: 20 | F19: 46206 | G19: 32 | H19: Amit
A20: O019 | B20: R007 | C20: Surat | D20: 947 | E20: 30 | F20: 46205 | G20: 65
A21: O020 | B21: R004 | C21: Vadodara | D21: 1013 | E21: 30 | F21: 46204 | G21: 59 | H21: Neha
A22: O021 | B22: R008 | C22: Vadodara | D22: 1216 | E22: 50 | F22: 46211 | G22: 64 | H22: Amit
A23: O022 | B23: R003 | C23: Surat | D23: 321 | E23: 50 | F23: 46228 | G23: 48
A24: O023 | B24: R008 | C24: Vadodara | D24: 297 | E24: 40 | F24: 46231 | G24: 25 | H24: Neha
A25: O024 | B25: R005 | C25: Rajkot | D25: 251 | E25: 50 | F25: 46209 | G25: 37 | H25: Priya
A26: O025 | B26: R002 | C26: Ahmedabad | D26: 872 | E26: 70 | F26: 46208 | G26: 31
A27: O026 | B27: R008 | C27: Vadodara | D27: 281 | E27: 40 | F27: 46234 | G27: 30
A28: O027 | B28: R008 | C28: Vadodara | D28: 237 | E28: 30 | F28: 46229 | G28: 45 | H28: Amit
A29: O028 | B29: R006 | C29: Ahmedabad | D29: 1052 | E29: 50 | F29: 46232 | G29: 59 | H29: Priya
A30: O029 | B30: R005 | C30: Rajkot | D30: 464 | E30: 60 | F30: 46212 | G30: 59 | H30: Amit
A31: O030 | B31: R001 | C31: Rajkot | D31: 963 | E31: 70 | F31: 46234 | G31: 30
A32: O031 | B32: R001 | C32: Rajkot | D32: 721 | E32: 60 | F32: 46224 | G32: 42 | H32: Amit
A33: O032 | B33: R007 | C33: Surat | D33: 706 | E33: 70 | F33: 46228 | G33: 47 | H33: Amit
A34: O033 | B34: R003 | C34: Surat | D34: 470 | E34: 20 | F34: 46207 | G34: 47 | H34: Amit
A35: O034 | B35: R001 | C35: Rajkot | D35: 1095 | E35: 30 | F35: 46231 | G35: 26 | H35: Rahul
A36: O035 | B36: R005 | C36: Rajkot | D36: 439 | E36: 40 | F36: 46234 | G36: 56 | H36: Neha
A37: O036 | B37: R007 | C37: Surat | D37: 1191 | E37: 30 | F37: 46209 | G37: 61 | H37: Amit
A38: O037 | B38: R003 | C38: Surat | D38: 953 | E38: 30 | F38: 46227 | G38: 67 | H38: Karan
A39: O038 | B39: R001 | C39: Rajkot | D39: 1213 | E39: 70 | F39: 46229 | G39: 25 | H39: Rahul
A40: O039 | B40: R007 | C40: Surat | D40: 1130 | E40: 20 | F40: 46228 | G40: 47 | H40: Karan
...

Sheet Restaurant_Details
A1: Restaurant ID | B1: Restaurant Name | C1: City
A2: R001 | B2: Spice Hub | C2: Rajkot
A3: R002 | B3: Food Palace | C3: Ahmedabad
A4: R003 | B4: Pizza Corner | C4: Surat
A5: R004 | B5: Biryani House | C5: Vadodara
A6: R005 | B6: Tandoori Tales | C6: Rajkot
A7: R006 | B7: Dragon Wok | C7: Ahmedabad
A8: R007 | B8: Pasta Street | C8: Surat
A9: R008 | B9: Dosa Junction | C9: Vadodara

Sheet Cleaned_Orders
A1: Order ID | B1: Restaurant ID | C1: City | D1: Order Amount | E1: Delivery Charge | F1: Delivery Date | G1: Delivery Time (min) | H1: Delivery Partner | I1: Restaurant Name | J1: Day of Week
A2: O001 | B2: R003 | C2: Surat | D2: 1036 | E2: 70 | F2: 46224 | G2: 48 | H2: Neha | I2: =IFERROR(VLOOKUP(B2,Restaurant_Details!$A$2:$C$9,2,FALSE()),"Not Found") -> Pizza Corner | J2: =TEXT(F2,"dddd") -> Tuesday
A3: O002 | B3: R008 | C3: Vadodara | D3: 622 | E3: 50 | F3: 46209 | G3: 54 | H3: Karan | I3: =IFERROR(VLOOKUP(B3,Restaurant_Details!$A$2:$C$9,2,FALSE()),"Not Found") -> Dosa Junction | J3: =TEXT(F3,"dddd") -> Monday
A4: O003 | B4: R004 | C4: Vadodara | D4: 186 | E4: 20 | F4: 46233 | G4: 45 | H4: Karan | I4: =IFERROR(VLOOKUP(B4,Restaurant_Details!$A$2:$C$9,2,FALSE()),"Not Found") -> Biryani House | J4: =TEXT(F4,"dddd") -> Thursday
A5: O004 | B5: R007 | C5: Surat | D5: 321 | E5: 30 | F5: 46233 | G5: 36 | H5: Amit | I5: =IFERROR(VLOOKUP(B5,Restaurant_Details!$A$2:$C$9,2,FALSE()),"Not Found") -> Pasta Street | J5: =TEXT(F5,"dddd") -> Thursday
A6: O005 | B6: R001 | C6: Rajkot | D6: 1074 | E6: 70 | F6: 46223 | G6: 48 | H6: Priya | I6: =IFERROR(VLOOKUP(B6,Restaurant_Details!$A$2:$C$9,2,FALSE()),"Not Found") -> Spice Hub | J6: =TEXT(F6,"dddd") -> Monday
A7: O006 | B7: R001 | C7: Rajkot | D7: 853 | E7: 60 | F7: 46226 | G7: 53 | H7: Rahul | I7: =IFERROR(VLOOKUP(B7,Restaurant_Details!$A$2:$C$9,2,FALSE()),"Not Found") -> Spice Hub | J7: =TEXT(F7,"dddd") -> Thursday
A8: O007 | B8: R006 | C8: Ahmedabad | D8: 227 | E8: 30 | F8: 46207 | G8: 27 | H8: Rahul | I8: =IFERROR(VLOOKUP(B8,Restaurant_Details!$A$2:$C$9,2,FALSE()),"Not Found") -> Dragon Wok | J8: =TEXT(F8,"dddd") -> Saturday
A9: O008 | B9: R008 | C9: Vadodara | D9: 509 | E9: 60 | F9: 46214 | G9: 68 | H9: Priya | I9: =IFERROR(VLOOKUP(B9,Restaurant_Details!$A$2:$C$9,2,FALSE()),"Not Found") -> Dosa Junction | J9: =TEXT(F9,"dddd") -> Saturday
A10: O009 | B10: R008 | C10: Vadodara | D10: 489 | E10: 30 | F10: 46205 | G10: 64 | H10: Priya | I10: =IFERROR(VLOOKUP(B10,Restaurant_Details!$A$2:$C$9,2,FALSE()),"Not Found") -> Dosa Junction | J10: =TEXT(F10,"dddd") -> Thursday
A11: O010 | B11: R004 | C11: Vadodara | D11: 332 | E11: 30 | F11: 46225 | G11: 35 | H11: Unassigned | I11: =IFERROR(VLOOKUP(B11,Restaurant_Details!$A$2:$C$9,2,FALSE()),"Not Found") -> Biryani House | J11: =TEXT(F11,"dddd") -> Wednesday
A12: O011 | B12: R002 | C12: Ahmedabad | D12: 430 | E12: 60 | F12: 46221 | G12: 52 | H12: Priya | I12: =IFERROR(VLOOKUP(B12,Restaurant_Details!$A$2:$C$9,2,FALSE()),"Not Found") -> Food Palace | J12: =TEXT(F12,"dddd") -> Saturday
A13: O012 | B13: R004 | C13: Vadodara | D13: 878 | E13: 30 | F13: 46217 | G13: 56 | H13: Neha | I13: =IFERROR(VLOOKUP(B13,Restaurant_Details!$A$2:$C$9,2,FALSE()),"Not Found") -> Biryani House | J13: =TEXT(F13,"dddd") -> Tuesday
... A41: O040 | B41: R003 | C41: Surat | D41: 657 | E41: 40 | F41: 46223 | G41: 66 | H41: Neha | I41: =IFERROR(VLOOKUP(B41,Restaurant_Details!$A$2:$C$9,2,FALSE()),"Not Found") -> Pizza Corner | J41: =TEXT(F41,"dddd") -> Monday

Sheet Lookup_Practice
A1: Order ID | B1: Restaurant ID | C1: Restaurant Name – XLOOKUP | D1: Restaurant Name – VLOOKUP
A2: O001 | B2: R003 | C2: =xlookup(B2,Restaurant_Details!$A$2:$A$9,Restaurant_Details!$B$2:$B$9,"Not Found") -> #NAME? | D2: =VLOOKUP(B2,Restaurant_Details!$A$2:$C$9,2,FALSE()) -> Pizza Corner
A3: O002 | B3: R008 | C3: =xlookup(B3,Restaurant_Details!$A$2:$A$9,Restaurant_Details!$B$2:$B$9,"Not Found") -> #NAME? | D3: =VLOOKUP(B3,Restaurant_Details!$A$2:$C$9,2,FALSE()) -> Dosa Junction
A4: O003 | B4: R004 | C4: =xlookup(B4,Restaurant_Details!$A$2:$A$9,Restaurant_Details!$B$2:$B$9,"Not Found") -> #NAME? | D4: =VLOOKUP(B4,Restaurant_Details!$A$2:$C$9,2,FALSE()) -> Biryani House
A5: O004 | B5: R007 | C5: =xlookup(B5,Restaurant_Details!$A$2:$A$9,Restaurant_Details!$B$2:$B$9,"Not Found") -> #NAME? | D5: =VLOOKUP(B5,Restaurant_Details!$A$2:$C$9,2,FALSE()) -> Pasta Street
A6: O005 | B6: R001 | C6: =xlookup(B6,Restaurant_Details!$A$2:$A$9,Restaurant_Details!$B$2:$B$9,"Not Found") -> #NAME? | D6: =VLOOKUP(B6,Restaurant_Details!$A$2:$C$9,2,FALSE()) -> Spice Hub
A7: O006 | B7: R001 | C7: =xlookup(B7,Restaurant_Details!$A$2:$A$9,Restaurant_Details!$B$2:$B$9,"Not Found") -> #NAME? | D7: =VLOOKUP(B7,Restaurant_Details!$A$2:$C$9,2,FALSE()) -> Spice Hub
A8: O007 | B8: R006 | C8: =xlookup(B8,Restaurant_Details!$A$2:$A$9,Restaurant_Details!$B$2:$B$9,"Not Found") -> #NAME? | D8: =VLOOKUP(B8,Restaurant_Details!$A$2:$C$9,2,FALSE()) -> Dragon Wok
A9: O008 | B9: R008 | C9: =xlookup(B9,Restaurant_Details!$A$2:$A$9,Restaurant_Details!$B$2:$B$9,"Not Found") -> #NAME? | D9: =VLOOKUP(B9,Restaurant_Details!$A$2:$C$9,2,FALSE()) -> Dosa Junction
A10: O009 | B10: R008 | C10: =xlookup(B10,Restaurant_Details!$A$2:$A$9,Restaurant_Details!$B$2:$B$9,"Not Found") -> #NAME? | D10: =VLOOKUP(B10,Restaurant_Details!$A$2:$C$9,2,FALSE()) -> Dosa Junction
A11: O010 | B11: R004 | C11: =xlookup(B11,Restaurant_Details!$A$2:$A$9,Restaurant_Details!$B$2:$B$9,"Not Found") -> #NAME? | D11: =VLOOKUP(B11,Restaurant_Details!$A$2:$C$9,2,FALSE()) -> Biryani House
A12: O011 | B12: R002 | C12: =xlookup(B12,Restaurant_Details!$A$2:$A$9,Restaurant_Details!$B$2:$B$9,"Not Found") -> #NAME? | D12: =VLOOKUP(B12,Restaurant_Details!$A$2:$C$9,2,FALSE()) -> Food Palace
A13: O012 | B13: R004 | C13: =xlookup(B13,Restaurant_Details!$A$2:$A$9,Restaurant_Details!$B$2:$B$9,"Not Found") -> #NAME? | D13: =VLOOKUP(B13,Restaurant_Details!$A$2:$C$9,2,FALSE()) -> Biryani House
... A16: O015 | B16: R008 | C16: =xlookup(B16,Restaurant_Details!$A$2:$A$9,Restaurant_Details!$B$2:$B$9,"Not Found") -> #NAME? | D16: =VLOOKUP(B16,Restaurant_Details!$A$2:$C$9,2,FALSE()) -> Dosa Junction

Sheet City_Summary
A1: City | B1: Total Orders | C1: Total Delivery Charges | D1: Average Delivery Time
A2: Rajkot | B2: =COUNTIF(Cleaned_Orders!$C$2:$C$41,A2) -> 10 | C2: =SUMIF(Cleaned_Orders!$C$2:$C$41,A2,Cleaned_Orders!$E$2:$E$41) -> 530 | D2: =ROUND(AVERAGEIF(Cleaned_Orders!$C$2:$C$41,A2,Cleaned_Orders!$G$2:$G$41),1) -> 40.8
A3: Ahmedabad | B3: =COUNTIF(Cleaned_Orders!$C$2:$C$41,A3) -> 5 | C3: =SUMIF(Cleaned_Orders!$C$2:$C$41,A3,Cleaned_Orders!$E$2:$E$41) -> 270 | D3: =ROUND(AVERAGEIF(Cleaned_Orders!$C$2:$C$41,A3,Cleaned_Orders!$G$2:$G$41),1) -> 43
A4: Surat | B4: =COUNTIF(Cleaned_Orders!$C$2:$C$41,A4) -> 12 | C4: =SUMIF(Cleaned_Orders!$C$2:$C$41,A4,Cleaned_Orders!$E$2:$E$41) -> 450 | D4: =ROUND(AVERAGEIF(Cleaned_Orders!$C$2:$C$41,A4,Cleaned_Orders!$G$2:$G$41),1) -> 50.3
A5: Vadodara | B5: =COUNTIF(Cleaned_Orders!$C$2:$C$41,A5) -> 13 | C5: =SUMIF(Cleaned_Orders!$C$2:$C$41,A5,Cleaned_Orders!$E$2:$E$41) -> 520 | D5: =ROUND(AVERAGEIF(Cleaned_Orders!$C$2:$C$41,A5,Cleaned_Orders!$G$2:$G$41),1) -> 48.6

Sheet Top_Restaurants
A1: Restaurant Name | B1: Order Count
A2: Dosa Junction | B2: =COUNTIF(Cleaned_Orders!$I$2:$I$41,A2) -> 8
A3: Pasta Street | B3: =COUNTIF(Cleaned_Orders!$I$2:$I$41,A3) -> 6
A4: Pizza Corner | B4: =COUNTIF(Cleaned_Orders!$I$2:$I$41,A4) -> 6
A5: Spice Hub | B5: =COUNTIF(Cleaned_Orders!$I$2:$I$41,A5) -> 6
A6: Biryani House | B6: =COUNTIF(Cleaned_Orders!$I$2:$I$41,A6) -> 5
A7: Tandoori Tales | B7: =COUNTIF(Cleaned_Orders!$I$2:$I$41,A7) -> 4
A8: Dragon Wok | B8: =COUNTIF(Cleaned_Orders!$I$2:$I$41,A8) -> 3
A9: Food Palace | B9: 2

Sheet City_Filter
A1: City Filter Values | C1: Use these values when creating an Excel Slicer on a PivotTable based on Cleaned_Orders.
A2: All Cities
A3: Rajkot
A4: Ahmedabad
A5: Surat
A6: Vadodara
